<?xml version="1.0"?>
<robot name="Tanker" xmlns:xacro="http://ros.org/wiki/xacro">

  <link name="base_footprint">
  </link>

	<!-- <BASE>-->
  <link name="base_link">
    <visual>
      <origin xyz="0.025 -0.185 0.03" rpy="1.57075 0 3.142"/>
      <geometry>
        <mesh filename="package://automonomus_projek/mesh/tiger_1_hull_h1.stl" scale="0.01 0.01 0.01"/>
        <!-- <box size="0.5 0.3 0.15"/> -->
      </geometry>
      <material name="Cyan">
        <color rgba="0 1.0 1.0 1.0"/>
      </material>
    </visual>
    <collision>
      <origin xyz="0 0 0" rpy="0 0 0"/>
      <geometry>
        <box size="0.5 0.3 0.15"/>
      </geometry>
    </collision>
    <inertial>
      <origin xyz="0 0 0" rpy="0 0 0"/>
      <!-- <geometry>
        <box size="0.5 0.3 0.06"/>
      </geometry> -->
      <mass value="10"/>
      <inertia ixx="1.0"  ixy="0"  ixz="0" iyy="1.0" iyz="0" izz="1.0" />
      <!-- <inertia ixx="0.211"  ixy="0"  ixz="0" iyy="0.078" iyz="0" izz="0.283" /> -->
    </inertial>
  </link>
  
  
     <!-- <NECK>-->
  <link name="neck_link">
    <visual>
      <origin xyz="0 0 0" rpy="0 0 0"/>
      <geometry>
       <box size="0.25 0.22 0.02"/>
      </geometry>
      <material name="Cyan">
        <color rgba="0 1.0 1.0 1.0"/>
      </material>
    </visual>
    <collision>
      <origin xyz="0 0 0" rpy="0 1.57075 0"/>
      <geometry>
        <sphere radius="0.1"/>
      </geometry>
    </collision>
    <inertial>
      <origin xyz="0 0 0" rpy="0 1.57075 0"/>
      <mass value="10"/>
      <inertia ixx="1.0"  ixy="0"  ixz="0" iyy="1.0" iyz="0" izz="1.0" />
    </inertial>
  </link>
  
  	<!-- <HEAD>-->
  <link name="head_link">
    <visual>
      <origin xyz="-0.15 0.21 0.09" rpy="1.57075 0 1.57075"/>
      <geometry>
        <mesh filename="package://automonomus_projek/mesh/Tiger_1_turret_top.stl" scale="0.01 0.01 0.01"/>
        <!-- <sphere radius="0.1"/> -->
      </geometry>
      <material name="Cyan">
        <color rgba="0 1.0 1.0 1.0"/>
      </material>
    </visual>
    <collision>
      <origin xyz="0 0 0" rpy="0 0 0"/>
      <geometry>
        <sphere radius="0.1"/>
      </geometry>
    </collision>
    <inertial>
      <origin xyz="0 0 0" rpy="0 0 0"/>
      <mass value="10"/>
      <inertia ixx="1.0"  ixy="0"  ixz="0" iyy="1.0" iyz="0" izz="1.0" />
    </inertial>
  </link>
  
  <!-- <CAMERA>-->
  <link name="camera_link">
    <visual>
      <origin rpy="1.57075 0 1.57075" xyz="-0.04 -0.01 0"/>
      <geometry>
      <mesh filename="package://automonomus_projek/mesh/Logitech c270 Assembly.stl" scale="0.0005 0.0005 0.0005"/>
        <!--<cylinder length="0.05" radius="0.11"/> -->
      </geometry>
      <material name="Black">
        <color rgba="0 0 0 1"/>
      </material>
    </visual>
    <inertial>
      <origin rpy="1.57075 0 0" xyz="0 0 0"/>
      <mass value="10"/>
      <inertia ixx="1.0"  ixy="0"  ixz="0" iyy="1.0" iyz="0" izz="1.0" />
    </inertial>
  </link>
  
	<!-- <FRONT RIGHT WHEEL>-->
  <link name="front_right_wheel">
    <visual>
      <origin rpy="1.57075 0 3.142" xyz="0 -0.085 0"/>
      <geometry>
      <mesh filename="package://automonomus_projek/mesh/front_rw.STL" scale="0.28 0.28 0.28"/>
        <!--<cylinder length="0.05" radius="0.11"/> -->
      </geometry>
      <material name="Black">
        <color rgba="0 0 0 1"/>
      </material>
    </visual>
    <collision>
      <origin rpy="1.57075 0 0" xyz="0 0 0"/>
      <geometry>
        <cylinder length="0.05" radius="0.11"/>
      </geometry>
    </collision>
    <inertial>
      <origin rpy="1.57075 0 0" xyz="0 0 0"/>
      <!-- <geometry>
        <cylinder length="0.05" radius="0.11"/>
      </geometry> -->
      <mass value="10"/>
      <inertia ixx="1.0"  ixy="0"  ixz="0" iyy="1.0" iyz="0" izz="1.0" />
      <!-- <inertia ixx="0.0323"  ixy="0"  ixz="0" iyy="0.0323" iyz="0" izz="0.0605" /> -->
    </inertial>
  </link>

	<!-- < FRONT LEFT WHEEL>-->
  <link name="front_left_wheel">
    <visual>
      <origin rpy="-1.57075 0 3.142" xyz="0 0.085 0"/>
      <geometry>
      <mesh filename="package://automonomus_projek/mesh/front_rw.STL" scale="0.28 0.28 0.28"/>
      </geometry>
      <material name="Black">
        <color rgba="0 0 0 1"/>
      </material>
    </visual>
    <collision>
      <origin rpy="1.57075 0 0" xyz="0 0 0"/>
      <geometry>
        <cylinder length="0.05" radius="0.11"/>
      </geometry>
    </collision>
    <inertial>
      <origin rpy="1.57075 0 0" xyz="0 0 0"/>
      <!-- <geometry>
        <cylinder length="0.05" radius="0.11"/>
      </geometry> -->
      <mass value="10"/>
      <inertia ixx="1.0"  ixy="0"  ixz="0" iyy="1.0" iyz="0" izz="1.0" />
      <!-- <inertia ixx="0.0323"  ixy="0"  ixz="0" iyy="0.0323" iyz="0" izz="0.0605" /> -->
    </inertial>
  </link>

	<!-- <REAR RIGHT WHEEL>-->
  <link name="rear_right_wheel">
    <visual>
      <origin rpy="1.57075 0 3.142" xyz="0 -0.085 0"/>
      <geometry>
      <mesh filename="package://automonomus_projek/mesh/front_rw.STL" scale="0.28 0.28 0.28"/>
      </geometry>
      <material name="Black">
        <color rgba="0 0 0 1"/>
      </material>
    </visual>
    <collision>
      <origin rpy="1.57075 0 0" xyz="0 0 0"/>
      <geometry>
        <cylinder length="0.05" radius="0.11"/>
      </geometry>
    </collision>
    <inertial>
      <origin rpy="1.57075 0 0" xyz="0 0 0"/>
      <!-- <geometry>
        <cylinder length="0.05" radius="0.11"/>
      </geometry> -->
      <mass value="10"/>
      <inertia ixx="1.0"  ixy="0"  ixz="0" iyy="1.0" iyz="0" izz="1.0" />
      <!-- <inertia ixx="0.0323"  ixy="0"  ixz="0" iyy="0.0323" iyz="0" izz="0.0605" /> -->
    </inertial>
  </link>

	<!-- <REAR LEFT WHEEL>-->
  <link name="rear_left_wheel">
    <visual>
      <origin rpy="-1.57075 0 3.142" xyz="0 0.085 0"/>
      <geometry>
      <mesh filename="package://automonomus_projek/mesh/front_rw.STL" scale="0.28 0.28 0.28"/>
      </geometry>
       <material name="Black">
        <color rgba="0 0 0 1"/>
      </material>
    </visual>
    <collision>
      <origin rpy="1.57075 0 0" xyz="0 0 0"/>
      <geometry>
        <cylinder length="0.05" radius="0.11"/>
      </geometry>
    </collision>
    <inertial>
      <origin rpy="1.57075 0 0" xyz="0 0 0"/>
      <!-- <geometry>
        <cylinder length="0.05" radius="0.11"/>
      </geometry> -->
      <mass value="10"/>
      <inertia ixx="1.0"  ixy="0"  ixz="0" iyy="1.0" iyz="0" izz="1.0" />
      <!-- <inertia ixx="0.0323"  ixy="0"  ixz="0" iyy="0.0323" iyz="0" izz="0.0605" /> -->
    </inertial>
  </link>
  

<!-- Joint -->

  <joint name="footprint_to_base" type="fixed">
    <origin rpy="0 0 0" xyz="0 0 0"/>
    <parent link="base_footprint"/>
    <child link="base_link"/>
  </joint>
  
  <joint name="neck_to_base" type="fixed">
    <origin rpy="0 0 0" xyz="0 0 0.085"/>
    <parent link="base_link"/>
    <child link="neck_link"/>
  </joint>
  
  <joint name="camera_to_head" type="fixed">
    <origin rpy="0 0 0" xyz="0.17 -0.01 0.08"/>
    <parent link="head_link"/>
    <child link="camera_link"/>
  </joint>
  
  <joint name="head_to_base" type="continuous">
    <origin rpy="0 0 0" xyz="0 0 0.085"/>
    <parent link="base_link"/>
    <child link="head_link"/>
    <axis xyz="0 0 1"/>
  </joint>
  
  <!-- <joint name="barrel_to_head" type="revolute">
    <axis xyz="0 1 0"/>
    <limit effort="1000.0" lower="-0.6" upper="0" velocity="1"/>
    <origin rpy="0 0 0" xyz="0 0 0.05"/>
    <parent link="head_link"/>
    <child link="barrel_link"/>
  </joint> -->

  <joint name="base_to_front_right_wheel" type="continuous">
    <origin rpy="0 0 0" xyz="0.13 0.175 -0.07"/>
    <parent link="base_link"/>
    <child link="front_right_wheel"/>
    <axis xyz="0 1 0"/>
  </joint>

  <joint name="base_to_front_left_wheel" type="continuous">
    <origin rpy="0 0 0" xyz="0.13 -0.175 -0.07"/>
    <parent link="base_link"/>
    <child link="front_left_wheel"/>
    <axis xyz="0 1 0"/>
  </joint>
  
  <joint name="base_to_rear_right_wheel" type="continuous">
    <origin rpy="0 0 0" xyz="-0.13 0.175 -0.07"/>
    <parent link="base_link"/>
    <child link="rear_right_wheel"/>
    <axis xyz="0 1 0"/>
  </joint>

  <joint name="base_to_rear_left_wheel" type="continuous">
    <origin rpy="0 0 0" xyz="-0.13 -0.175 -0.07"/>
    <parent link="base_link"/>
    <child link="rear_left_wheel"/>
    <axis xyz="0 1 0"/>
  </joint>



<!-- Transmission -->
  <transmission name="front_left_wheel_transmission">
    <type> transmission_interface/SimpleTransmission </type>
    <joint name="base_to_front_left_wheel">
      <!-- <hardwareInterface>hardware_interface/VelocityJointInterface</hardwareInterface> -->
      <hardwareInterface>VelocityJointInterface</hardwareInterface>
    </joint>
    <actuator name="front_left_wheel_actuator">
      <mechanicalReduction>7</mechanicalReduction>
      <!-- <hardwareInterface>VelocityJointInterface</hardwareInterface> -->
    </actuator>
  </transmission>

  <transmission name="front_right_wheel_transmission">
    <type> transmission_interface/SimpleTransmission </type>
    <joint name="base_to_front_right_wheel">
      <!-- <hardwareInterface>hardware_interface/VelocityJointInterface</hardwareInterface> -->
      <hardwareInterface>VelocityJointInterface</hardwareInterface>
    </joint>
    <actuator name="front_right_wheel_actuator">
      <mechanicalReduction>7</mechanicalReduction>
      <!-- <hardwareInterface>VelocityJointInterface</hardwareInterface> -->
    </actuator>
  </transmission>

  <transmission name="rear_right_wheel_transmission">
    <type> transmission_interface/SimpleTransmission </type>
    <joint name="base_to_rear_right_wheel">
      <!-- <hardwareInterface>hardware_interface/VelocityJointInterface</hardwareInterface> -->
      <hardwareInterface>VelocityJointInterface</hardwareInterface>
    </joint>
    <actuator name="rear_right_wheel_actuator">
      <mechanicalReduction>7</mechanicalReduction>
      <!-- <hardwareInterface>VelocityJointInterface</hardwareInterface> -->
    </actuator>
  </transmission>

  <transmission name="rear_left_wheel_transmission">
    <type> transmission_interface/SimpleTransmission </type>
    <joint name="base_to_rear_left_wheel">
      <!-- <hardwareInterface>hardware_interface/VelocityJointInterface</hardwareInterface> -->
      <hardwareInterface>VelocityJointInterface</hardwareInterface>
    </joint>
    <actuator name="rear_left_wheel_actuator">
      <mechanicalReduction>7</mechanicalReduction>
      <!-- <hardwareInterface>VelocityJointInterface</hardwareInterface> -->
    </actuator>
  </transmission>

  <transmission name="head_swivel_trans">
    <type>transmission_interface/SimpleTransmission</type>
    <actuator name="$head_swivel_motor">
      <mechanicalReduction>1</mechanicalReduction>
    </actuator>
    <joint name="head_to_base">
      <hardwareInterface>PositionJointInterface</hardwareInterface>
    </joint>
  </transmission>
  
  
<!-- Gazebo Camera plugin -->  
 <gazebo reference="camera_link">
    <sensor type="camera" name="camera1">
      <update_rate>30.0</update_rate>
      <camera name="head">
        <horizontal_fov>1.3962634</horizontal_fov>
        <image>
          <width>800</width>
          <height>800</height>
          <format>R8G8B8</format>
        </image>
        <clip>
          <near>0.02</near>
          <far>300</far>
        </clip>
        <noise>
          <type>gaussian</type>
          <!-- Noise is sampled independently per pixel on each frame.
               That pixel's noise value is added to each of its color
               channels, which at that point lie in the range [0,1]. -->
          <mean>0.0</mean>
          <stddev>0.007</stddev>
        </noise>
      </camera>
      <plugin name="camera_controller" filename="libgazebo_ros_camera.so">
        <alwaysOn>true</alwaysOn>
        <updateRate>0.0</updateRate>
        <cameraName>tank/camera1</cameraName>
        <imageTopicName>image_raw</imageTopicName>
        <cameraInfoTopicName>camera_info</cameraInfoTopicName>
        <frameName>camera_link</frameName>
        <hackBaseline>0.07</hackBaseline>
        <distortionK1>0.0</distortionK1>
        <distortionK2>0.0</distortionK2>
        <distortionK3>0.0</distortionK3>
        <distortionT1>0.0</distortionT1>
        <distortionT2>0.0</distortionT2>
      </plugin>
    </sensor>
  </gazebo>


<!-- Gazebo plugin for ROS Control -->
  <gazebo>
    <plugin name="gazebo_ros_control" filename="libgazebo_ros_control.so">
      <robotNamespace>/</robotNamespace>
    </plugin>
  </gazebo>

</robot>
